{
  "session_start": "2025-09-15T21:19:01.040265",
  "total_fixes": 2,
  "errors": {
    "d2b86155325a": {
      "error_type": "ImportError",
      "error_message": "Import could not be resolved",
      "file_path": "error_tracker_cli.py",
      "line_number": 13,
      "count": 1,
      "first_occurrence": "2025-09-15T21:19:01.040294",
      "last_occurrence": "2025-09-15T21:19:01.040294"
    },
    "0c6eee680f93": {
      "error_type": "TypeError",
      "error_message": "Type annotation error",
      "file_path": "simple_error_tracker.py",
      "line_number": 59,
      "count": 1,
      "first_occurrence": "2025-09-15T21:19:45.225570",
      "last_occurrence": "2025-09-15T21:19:45.225570"
    }
  },
  "history": [
    {
      "timestamp": "2025-09-15T21:19:01.040294",
      "error_hash": "d2b86155325a",
      "error_type": "ImportError",
      "error_message": "Import could not be resolved",
      "file_path": "error_tracker_cli.py",
      "line_number": 13,
      "fix_description": "Added try-except block for import handling",
      "count": 1
    },
    {
      "timestamp": "2025-09-15T21:19:45.225570",
      "error_hash": "0c6eee680f93",
      "error_type": "TypeError",
      "error_message": "Type annotation error",
      "file_path": "simple_error_tracker.py",
      "line_number": 59,
      "fix_description": null,
      "count": 1
    }
  ]
}